Workbook

Sheet Titles
A2: Housing Start Data in Centres 10,000 Population and Over
A4: February 2025 - 2026
A5: January - February 2025 - 2026
A7: Footnotes
A8: 1 Data for 2023, 2024 and 2025 based on 2021 Census Definitions.
A10: Source: CMHC Starts and Completion Survey, Market Absorption Survey
A12: 1 Data for 2023, 2024 and 2025 based on 2021 Census Definitions.
A14: 1 2024 and 2025 data based on 2021 Census Definitions.
A20: Données provisoires sur les mises en chantier d'habitations
A21: 2024
A22: 2025
A23: 2026

Sheet Index
B1: CMHC HOUSING MARKET INFORMATION
B2: Monthly Housing Starts and Other Construction Data
B4: Source: CMHC Starts and Completions Survey and Market Absorption Survey
B5: © 2025 Canada Mortgage and Housing Corporation
B7: TABLE OF CONTENTS
B8: The table of contents below provides a brief description of the contents in each tab.
B10: Note to readers
B12: Table 1: Housing Start Data in Centres 10,000 Population and Over
B14: Table 2: Housing Start Data in Centres 10,000 Population and Over (Cumulative)
B16: Table 3: Dwelling Starts in Urban Centres and Canada, Seasonally Adjusted at Annual Rates
B18: Table 4: Dwelling Starts in Urban Centres, by Region, Seasonally Adjusted at Annual Rates
B20: Table 5: Dwelling Starts in Urban Centres, by Region, Seasonally Adjusted at Annual Rates
... B38: Concepts and Definitions

Sheet Notes
A1: Note to readers:
A3: The following notes to readers are designed to provide an update to clients on changes or corrections made to our housing surveys methodology or data.
A5: Geography
A6: As of January, 2023, data contained within this publication reflect 2021 Census geography in line with Statistics Canada's Standard Geographical Classification (SGC). The following is a summary of geography changes:
A8: Census Metropolitan Area (CMA) and Census Agglomeration (CA) changes:
A9: 6 new CMAs: Chilliwack, Drummondville, Fredericton, Kamloops, Nanaimo and Red Deer
A10: Ottawa CMA: Arnprior T and Carleton Place T are now merged with Ottawa CMA
A11: East Hants MD : almagated with Halifax CMA
A12: Essex T : merged with Windsor CMA
A13: Leamington MU : merged with Windsor CMA
A14: Joliette V: now a large CA (population 50,000+)
A15: Victoriaville V: now a large CA (population 50,000+)
... A32: April 2024 release: A special revision was made to seasonally adjusted dwelling starts for Sudbury/Grand Sudbury for the months of January, February and March 2024 (Table 12).

Sheet Table 1
A1: Table 1
A2: =Titles!A2 -> Housing Start Data in Centres 10,000 Population and Over
A4: =Titles!A4 -> February 2025 - 2026
A5: Area | C5: Single-Detached | F5: All Others | I5: Total
A6: Province
C7: =Titles!A22 -> 2025 | D7: =Titles!A23 -> 2026 | E7: % | F7: =Titles!A22 -> 2025 | G7: =Titles!A23 -> 2026 | H7: % | I7: =Titles!A22 -> 2025 | J7: =Titles!A23 -> 2026 | K7: %
A8: N.L. | C8: 20 | D8: 18 | E8: =IF(C8=D8,"-",IF((C8=0),"##",IF(ABS((D8/C8-1)*100)>=500,"##",(D8/C8-1)*100))) -> -10 | F8: 19 | G8: 27 | H8: =IF(F8=G8,"-",IF((F8=0),"##",IF(ABS((G8/F8-1)*100)>=500,"##",(G8/F8-1)*100))) -> 42.105263 | I8: =C8+F8 -> 39 | J8: =D8+G8 -> 45 | K8: =IF(I8=J8,"-",IF((I8=0),"##",IF(ABS((J8/I8-1)*100)>=500,"##",(J8/I8-1)*100))) -> 15.384615
A9: P.E.I. | C9: 15 | D9: 13 | E9: =IF(C9=D9,"-",IF((C9=0),"##",IF(ABS((D9/C9-1)*100)>=500,"##",(D9/C9-1)*100))) -> -13.333333 | F9: 48 | G9: 92 | H9: =IF(F9=G9,"-",IF((F9=0),"##",IF(ABS((G9/F9-1)*100)>=500,"##",(G9/F9-1)*100))) -> 91.666667 | I9: =C9+F9 -> 63 | J9: =D9+G9 -> 105 | K9: =IF(I9=J9,"-",IF((I9=0),"##",IF(ABS((J9/I9-1)*100)>=500,"##",(J9/I9-1)*100))) -> 66.666667
A10: N.S. | C10: 46 | D10: 43 | E10: =IF(C10=D10,"-",IF((C10=0),"##",IF(ABS((D10/C10-1)*100)>=500,"##",(D10/C10-1)*100))) -> -6.5217391 | F10: 435 | G10: 428 | H10: =IF(F10=G10,"-",IF((F10=0),"##",IF(ABS((G10/F10-1)*100)>=500,"##",(G10/F10-1)*100))) -> -1.6091954 | I10: =C10+F10 -> 481 | J10: =D10+G10 -> 471 | K10: =IF(I10=J10,"-",IF((I10=0),"##",IF(ABS((J10/I10-1)*100)>=500,"##",(J10/I10-1)*100))) -> -2.0790021
A11: N.B. | C11: 20 | D11: 9 | E11: =IF(C11=D11,"-",IF((C11=0),"##",IF(ABS((D11/C11-1)*100)>=500,"##",(D11/C11-1)*100))) -> -55 | F11: 270 | G11: 203 | H11: =IF(F11=G11,"-",IF((F11=0),"##",IF(ABS((G11/F11-1)*100)>=500,"##",(G11/F11-1)*100))) -> -24.814815 | I11: =C11+F11 -> 290 | J11: =D11+G11 -> 212 | K11: =IF(I11=J11,"-",IF((I11=0),"##",IF(ABS((J11/I11-1)*100)>=500,"##",(J11/I11-1)*100))) -> -26.896552
A12: Atlantic | C12: =SUM(C8:C11) -> 101 | D12: =SUM(D8:D11) -> 83 | E12: =IF(C12=D12,"-",IF((C12=0),"##",IF(ABS((D12/C12-1)*100)>=500,"##",(D12/C12-1)*100))) -> -17.821782 | F12: =SUM(F8:F11) -> 772 | G12: =SUM(G8:G11) -> 750 | H12: =IF(F12=G12,"-",IF((F12=0),"##",IF(ABS((G12/F12-1)*100)>=500,"##",(G12/F12-1)*100))) -> -2.8497409 | I12: =C12+F12 -> 873 | J12: =D12+G12 -> 833 | K12: =IF(I12=J12,"-",IF((I12=0),"##",IF(ABS((J12/I12-1)*100)>=500,"##",(J12/I12-1)*100))) -> -4.5819015
A13: Que. | C13: 178 | D13: 203 | E13: =IF(C13=D13,"-",IF((C13=0),"##",IF(ABS((D13/C13-1)*100)>=500,"##",(D13/C13-1)*100))) -> 14.044944 | F13: 2203 | G13: 2526 | H13: =IF(F13=G13,"-",IF((F13=0),"##",IF(ABS((G13/F13-1)*100)>=500,"##",(G13/F13-1)*100))) -> 14.661825 | I13: =C13+F13 -> 2381 | J13: =D13+G13 -> 2729 | K13: =IF(I13=J13,"-",IF((I13=0),"##",IF(ABS((J13/I13-1)*100)>=500,"##",(J13/I13-1)*100))) -> 14.615708
A14: Ont. | C14: 522 | D14: 387 | E14: =IF(C14=D14,"-",IF((C14=0),"##",IF(ABS((D14/C14-1)*100)>=500,"##",(D14/C14-1)*100))) -> -25.862069 | F14: 3467 | G14: 4278 | H14: =IF(F14=G14,"-",IF((F14=0),"##",IF(ABS((G14/F14-1)*100)>=500,"##",(G14/F14-1)*100))) -> 23.391982 | I14: =C14+F14 -> 3989 | J14: =D14+G14 -> 4665 | K14: =IF(I14=J14,"-",IF((I14=0),"##",IF(ABS((J14/I14-1)*100)>=500,"##",(J14/I14-1)*100))) -> 16.946603
A15: Man. | C15: 160 | D15: 139 | E15: =IF(C15=D15,"-",IF((C15=0),"##",IF(ABS((D15/C15-1)*100)>=500,"##",(D15/C15-1)*100))) -> -13.125 | F15: 159 | G15: 515 | H15: =IF(F15=G15,"-",IF((F15=0),"##",IF(ABS((G15/F15-1)*100)>=500,"##",(G15/F15-1)*100))) -> 223.89937 | I15: =C15+F15 -> 319 | J15: =D15+G15 -> 654 | K15: =IF(I15=J15,"-",IF((I15=0),"##",IF(ABS((J15/I15-1)*100)>=500,"##",(J15/I15-1)*100))) -> 105.01567
A16: Sask. | C16: 98 | D16: 126 | E16: =IF(C16=D16,"-",IF((C16=0),"##",IF(ABS((D16/C16-1)*100)>=500,"##",(D16/C16-1)*100))) -> 28.571429 | F16: 360 | G16: 251 | H16: =IF(F16=G16,"-",IF((F16=0),"##",IF(ABS((G16/F16-1)*100)>=500,"##",(G16/F16-1)*100))) -> -30.277778 | I16: =C16+F16 -> 458 | J16: =D16+G16 -> 377 | K16: =IF(I16=J16,"-",IF((I16=0),"##",IF(ABS((J16/I16-1)*100)>=500,"##",(J16/I16-1)*100))) -> -17.68559
A17: Alta. | C17: 1127 | D17: 956 | E17: =IF(C17=D17,"-",IF((C17=0),"##",IF(ABS((D17/C17-1)*100)>=500,"##",(D17/C17-1)*100))) -> -15.173026 | F17: 3068 | G17: 2338 | H17: =IF(F17=G17,"-",IF((F17=0),"##",IF(ABS((G17/F17-1)*100)>=500,"##",(G17/F17-1)*100))) -> -23.794003 | I17: =C17+F17 -> 4195 | J17: =D17+G17 -> 3294 | K17: =IF(I17=J17,"-",IF((I17=0),"##",IF(ABS((J17/I17-1)*100)>=500,"##",(J17/I17-1)*100))) -> -21.47795
A18: Prairies | C18: =SUM(C15:C17) -> 1385 | D18: =SUM(D15:D17) -> 1221 | E18: =IF(C18=D18,"-",IF((C18=0),"##",IF(ABS((D18/C18-1)*100)>=500,"##",(D18/C18-1)*100))) -> -11.841155 | F18: =SUM(F15:F17) -> 3587 | G18: =SUM(G15:G17) -> 3104 | H18: =IF(F18=G18,"-",IF((F18=0),"##",IF(ABS((G18/F18-1)*100)>=500,"##",(G18/F18-1)*100))) -> -13.465291 | I18: =C18+F18 -> 4972 | J18: =D18+G18 -> 4325 | K18: =IF(I18=J18,"-",IF((I18=0),"##",IF(ABS((J18/I18-1)*100)>=500,"##",(J18/I18-1)*100))) -> -13.012872
A19: B.C. | C19: 236 | D19: 247 | E19: =IF(C19=D19,"-",IF((C19=0),"##",IF(ABS((D19/C19-1)*100)>=500,"##",(D19/C19-1)*100))) -> 4.6610169 | F19: 1969 | G19: 3087 | H19: =IF(F19=G19,"-",IF((F19=0),"##",IF(ABS((G19/F19-1)*100)>=500,"##",(G19/F19-1)*100))) -> 56.780091 | I19: =C19+F19 -> 2205 | J19: =D19+G19 -> 3334 | K19: =IF(I19=J19,"-",IF((I19=0),"##",IF(ABS((J19/I19-1)*100)>=500,"##",(J19/I19-1)*100))) -> 51.201814
A20: Canada | C20: =SUM(C12:C14,C18:C19) -> 2422 | D20: =SUM(D12:D14,D18:D19) -> 2141 | E20: =IF(C20=D20,"-",IF((C20=0),"##",IF(ABS((D20/C20-1)*100)>=500,"##",(D20/C20-1)*100))) -> -11.601982 | F20: =SUM(F12:F14,F18:F19) -> 11998 | G20: =SUM(G12:G14,G18:G19) -> 13745 | H20: =IF(F20=G20,"-",IF((F20=0),"##",IF(ABS((G20/F20-1)*100)>=500,"##",(G20/F20-1)*100))) -> 14.56076 | I20: =C20+F20 -> 14420 | J20: =D20+G20 -> 15886 | K20: =IF(I20=J20,"-",IF((I20=0),"##",IF(ABS((J20/I20-1)*100)>=500,"##",(J20/I20-1)*100))) -> 10.166436
A21: Metropolitan Areas
A23: Abbotsford-Mission | C23: 4 | D23: 4 | E23: =IF(C23=D23,"-",IF((C23=0),"##",IF(ABS((D23/C23-1)*100)>=500,"##",(D23/C23-1)*100))) -> - | F23: 152 | G23: 7 | H23: =IF(F23=G23,"-",IF((F23=0),"##",IF(ABS((G23/F23-1)*100)>=500,"##",(G23/F23-1)*100))) -> -95.394737 | I23: =C23+F23 -> 156 | J23: =D23+G23 -> 11 | K23: =IF(I23=J23,"-",IF((I23=0),"##",IF(ABS((J23/I23-1)*100)>=500,"##",(J23/I23-1)*100))) -> -92.948718
A24: Barrie | C24: 12 | D24: 18 | E24: =IF(C24=D24,"-",IF((C24=0),"##",IF(ABS((D24/C24-1)*100)>=500,"##",(D24/C24-1)*100))) -> 50 | F24: 33 | G24: 30 | H24: =IF(F24=G24,"-",IF((F24=0),"##",IF(ABS((G24/F24-1)*100)>=500,"##",(G24/F24-1)*100))) -> -9.0909091 | I24: =C24+F24 -> 45 | J24: =D24+G24 -> 48 | K24: =IF(I24=J24,"-",IF((I24=0),"##",IF(ABS((J24/I24-1)*100)>=500,"##",(J24/I24-1)*100))) -> 6.6666667
A25: Belleville - Quinte West | C25: 10 | D25: 1 | E25: =IF(C25=D25,"-",IF((C25=0),"##",IF(ABS((D25/C25-1)*100)>=500,"##",(D25/C25-1)*100))) -> -90 | F25: 165 | G25: 0 | H25: =IF(F25=G25,"-",IF((F25=0),"##",IF(ABS((G25/F25-1)*100)>=500,"##",(G25/F25-1)*100))) -> -100 | I25: =C25+F25 -> 175 | J25: =D25+G25 -> 1 | K25: =IF(I25=J25,"-",IF((I25=0),"##",IF(ABS((J25/I25-1)*100)>=500,"##",(J25/I25-1)*100))) -> -99.428571
A26: Brantford | C26: 3 | D26: 19 | E26: =IF(C26=D26,"-",IF((C26=0),"##",IF(ABS((D26/C26-1)*100)>=500,"##",(D26/C26-1)*100))) -> ## | F26: 0 | G26: 0 | H26: =IF(F26=G26,"-",IF((F26=0),"##",IF(ABS((G26/F26-1)*100)>=500,"##",(G26/F26-1)*100))) -> - | I26: =C26+F26 -> 3 | J26: =D26+G26 -> 19 | K26: =IF(I26=J26,"-",IF((I26=0),"##",IF(ABS((J26/I26-1)*100)>=500,"##",(J26/I26-1)*100))) -> ##
A27: Calgary | C27: 500 | D27: 424 | E27: =IF(C27=D27,"-",IF((C27=0),"##",IF(ABS((D27/C27-1)*100)>=500,"##",(D27/C27-1)*100))) -> -15.2 | F27: 1907 | G27: 908 | H27: =IF(F27=G27,"-",IF((F27=0),"##",IF(ABS((G27/F27-1)*100)>=500,"##",(G27/F27-1)*100))) -> -52.385947 | I27: =C27+F27 -> 2407 | J27: =D27+G27 -> 1332 | K27: =IF(I27=J27,"-",IF((I27=0),"##",IF(ABS((J27/I27-1)*100)>=500,"##",(J27/I27-1)*100))) -> -44.661404
A28: Chilliwack | C28: 8 | D28: 7 | E28: =IF(C28=D28,"-",IF((C28=0),"##",IF(ABS((D28/C28-1)*100)>=500,"##",(D28/C28-1)*100))) -> -12.5 | F28: 42 | G28: 10 | H28: =IF(F28=G28,"-",IF((F28=0),"##",IF(ABS((G28/F28-1)*100)>=500,"##",(G28/F28-1)*100))) -> -76.190476 | I28: =C28+F28 -> 50 | J28: =D28+G28 -> 17 | K28: =IF(I28=J28,"-",IF((I28=0),"##",IF(ABS((J28/I28-1)*100)>=500,"##",(J28/I28-1)*100))) -> -66
A29: Drummondville | C29: 6 | D29: 10 | E29: =IF(C29=D29,"-",IF((C29=0),"##",IF(ABS((D29/C29-1)*100)>=500,"##",(D29/C29-1)*100))) -> 66.666667 | F29: 67 | G29: 33 | H29: =IF(F29=G29,"-",IF((F29=0),"##",IF(ABS((G29/F29-1)*100)>=500,"##",(G29/F29-1)*100))) -> -50.746269 | I29: =C29+F29 -> 73 | J29: =D29+G29 -> 43 | K29: =IF(I29=J29,"-",IF((I29=0),"##",IF(ABS((J29/I29-1)*100)>=500,"##",(J29/I29-1)*100))) -> -41.09589
A30: Edmonton | C30: 536 | D30: 425 | E30: =IF(C30=D30,"-",IF((C30=0),"##",IF(ABS((D30/C30-1)*100)>=500,"##",(D30/C30-1)*100))) -> -20.708955 | F30: 942 | G30: 1072 | H30: =IF(F30=G30,"-",IF((F30=0),"##",IF(ABS((G30/F30-1)*100)>=500,"##",(G30/F30-1)*100))) -> 13.800425 | I30: =C30+F30 -> 1478 | J30: =D30+G30 -> 1497 | K30: =IF(I30=J30,"-",IF((I30=0),"##",IF(ABS((J30/I30-1)*100)>=500,"##",(J30/I30-1)*100))) -> 1.285521
A31: Fredericton | C31: 9 | D31: 2 | E31: =IF(C31=D31,"-",IF((C31=0),"##",IF(ABS((D31/C31-1)*100)>=500,"##",(D31/C31-1)*100))) -> -77.777778 | F31: 0 | G31: 10 | H31: =IF(F31=G31,"-",IF((F31=0),"##",IF(ABS((G31/F31-1)*100)>=500,"##",(G31/F31-1)*100))) -> ## | I31: =C31+F31 -> 9 | J31: =D31+G31 -> 12 | K31: =IF(I31=J31,"-",IF((I31=0),"##",IF(ABS((J31/I31-1)*100)>=500,"##",(J31/I31-1)*100))) -> 33.333333
A32: Greater/Grand Sudbury | C32: 0 | D32: 1 | E32: =IF(C32=D32,"-",IF((C32=0),"##",IF(ABS((D32/C32-1)*100)>=500,"##",(D32/C32-1)*100))) -> ## | F32: 0 | G32: 3 | H32: =IF(F32=G32,"-",IF((F32=0),"##",IF(ABS((G32/F32-1)*100)>=500,"##",(G32/F32-1)*100))) -> ## | I32: =C32+F32 -> 0 | J32: =D32+G32 -> 4 | K32: =IF(I32=J32,"-",IF((I32=0),"##",IF(ABS((J32/I32-1)*100)>=500,"##",(J32/I32-1)*100))) -> ##
A33: Guelph | C33: 0 | D33: 2 | E33: =IF(C33=D33,"-",IF((C33=0),"##",IF(ABS((D33/C33-1)*100)>=500,"##",(D33/C33-1)*100))) -> ## | F33: 0 | G33: 6 | H33: =IF(F33=G33,"-",IF((F33=0),"##",IF(ABS((G33/F33-1)*100)>=500,"##",(G33/F33-1)*100))) -> ## | I33: =C33+F33 -> 0 | J33: =D33+G33 -> 8 | K33: =IF(I33=J33,"-",IF((I33=0),"##",IF(ABS((J33/I33-1)*100)>=500,"##",(J33/I33-1)*100))) -> ##
A34: Halifax | C34: 31 | D34: 20 | E34: =IF(C34=D34,"-",IF((C34=0),"##",IF(ABS((D34/C34-1)*100)>=500,"##",(D34/C34-1)*100))) -> -35.483871 | F34: 410 | G34: 383 | H34: =IF(F34=G34,"-",IF((F34=0),"##",IF(ABS((G34/F34-1)*100)>=500,"##",(G34/F34-1)*100))) -> -6.5853659 | I34: =C34+F34 -> 441 | J34: =D34+G34 -> 403 | K34: =IF(I34=J34,"-",IF((I34=0),"##",IF(ABS((J34/I34-1)*100)>=500,"##",(J34/I34-1)*100))) -> -8.61678
... A45: Oshawa | C45: 9 | D45: 24 | E45: =IF(C45=D45,"-",IF((C45=0),"##",IF(ABS((D45/C45-1)*100)>=500,"##",(D45/C45-1)*100))) -> 166.66667 | F45: 4 | G45: 38 | H45: =IF(F45=G45,"-",IF((F45=0),"##",IF(ABS((G45/F45-1)*100)>=500,"##",(G45/F45-1)*100))) -> ## | I45: =C45+F45 -> 13 | J45: =D45+G45 -> 62 | K45: =IF(I45=J45,"-",IF((I45=0),"##",IF(ABS((J45/I45-1)*100)>=500,"##",(J45/I45-1)*100))) -> 376.92308
A46: Ottawa-Gatineau | C46: =SUM(C47:C48) -> 143 | D46: =SUM(D47:D48) -> 110 | E46: =IF(C46=D46,"-",IF((C46=0),"##",IF(ABS((D46/C46-1)*100)>=500,"##",(D46/C46-1)*100))) -> -23.076923 | F46: =SUM(F47:F48) -> 952 | G46: =SUM(G47:G48) -> 1242 | H46: =IF(F46=G46,"-",IF((F46=0),"##",IF(ABS((G46/F46-1)*100)>=500,"##",(G46/F46-1)*100))) -> 30.462185 | I46: =C46+F46 -> 1095 | J46: =D46+G46 -> 1352 | K46: =IF(I46=J46,"-",IF((I46=0),"##",IF(ABS((J46/I46-1)*100)>=500,"##",(J46/I46-1)*100))) -> 23.47032
A47: Gatineau | C47: 18 | D47: 18 | E47: =IF(C47=D47,"-",IF((C47=0),"##",IF(ABS((D47/C47-1)*100)>=500,"##",(D47/C47-1)*100))) -> - | F47: 91 | G47: 210 | H47: =IF(F47=G47,"-",IF((F47=0),"##",IF(ABS((G47/F47-1)*100)>=500,"##",(G47/F47-1)*100))) -> 130.76923 | I47: =C47+F47 -> 109 | J47: =D47+G47 -> 228 | K47: =IF(I47=J47,"-",IF((I47=0),"##",IF(ABS((J47/I47-1)*100)>=500,"##",(J47/I47-1)*100))) -> 109.17431
A48: Ottawa | C48: 125 | D48: 92 | E48: =IF(C48=D48,"-",IF((C48=0),"##",IF(ABS((D48/C48-1)*100)>=500,"##",(D48/C48-1)*100))) -> -26.4 | F48: 861 | G48: 1032 | H48: =IF(F48=G48,"-",IF((F48=0),"##",IF(ABS((G48/F48-1)*100)>=500,"##",(G48/F48-1)*100))) -> 19.860627 | I48: =C48+F48 -> 986 | J48: =D48+G48 -> 1124 | K48: =IF(I48=J48,"-",IF((I48=0),"##",IF(ABS((J48/I48-1)*100)>=500,"##",(J48/I48-1)*100))) -> 13.995943
A49: Peterborough | C49: 9 | D49: 5 | E49: =IF(C49=D49,"-",IF((C49=0),"##",IF(ABS((D49/C49-1)*100)>=500,"##",(D49/C49-1)*100))) -> -44.444444 | F49: 1 | G49: 0 | H49: =IF(F49=G49,"-",IF((F49=0),"##",IF(ABS((G49/F49-1)*100)>=500,"##",(G49/F49-1)*100))) -> -100 | I49: =C49+F49 -> 10 | J49: =D49+G49 -> 5 | K49: =IF(I49=J49,"-",IF((I49=0),"##",IF(ABS((J49/I49-1)*100)>=500,"##",(J49/I49-1)*100))) -> -50
A50: Québec | C50: 31 | D50: 43 | E50: =IF(C50=D50,"-",IF((C50=0),"##",IF(ABS((D50/C50-1)*100)>=500,"##",(D50/C50-1)*100))) -> 38.709677 | F50: 493 | G50: 666 | H50: =IF(F50=G50,"-",IF((F50=0),"##",IF(ABS((G50/F50-1)*100)>=500,"##",(G50/F50-1)*100))) -> 35.091278 | I50: =C50+F50 -> 524 | J50: =D50+G50 -> 709 | K50: =IF(I50=J50,"-",IF((I50=0),"##",IF(ABS((J50/I50-1)*100)>=500,"##",(J50/I50-1)*100))) -> 35.305344
A51: Red Deer | C51: 7 | D51: 9 | E51: =IF(C51=D51,"-",IF((C51=0),"##",IF(ABS((D51/C51-1)*100)>=500,"##",(D51/C51-1)*100))) -> 28.571429 | F51: 2 | G51: 11 | H51: =IF(F51=G51,"-",IF((F51=0),"##",IF(ABS((G51/F51-1)*100)>=500,"##",(G51/F51-1)*100))) -> 450 | I51: =C51+F51 -> 9 | J51: =D51+G51 -> 20 | K51: =IF(I51=J51,"-",IF((I51=0),"##",IF(ABS((J51/I51-1)*100)>=500,"##",(J51/I51-1)*100))) -> 122.22222
A52: Regina | C52: 32 | D52: 49 | E52: =IF(C52=D52,"-",IF((C52=0),"##",IF(ABS((D52/C52-1)*100)>=500,"##",(D52/C52-1)*100))) -> 53.125 | F52: 302 | G52: 51 | H52: =IF(F52=G52,"-",IF((F52=0),"##",IF(ABS((G52/F52-1)*100)>=500,"##",(G52/F52-1)*100))) -> -83.112583 | I52: =C52+F52 -> 334 | J52: =D52+G52 -> 100 | K52: =IF(I52=J52,"-",IF((I52=0),"##",IF(ABS((J52/I52-1)*100)>=500,"##",(J52/I52-1)*100))) -> -70.05988
...

Sheet Table 2
A1: Table 2
A2: =Titles!A2 -> Housing Start Data in Centres 10,000 Population and Over
A4: =Titles!A5 -> January - February 2025 - 2026
A5: Area | C5: Single-Detached | F5: All Others | I5: Total
A6: Province
C7: =Titles!A22 -> 2025 | D7: =Titles!A23 -> 2026 | E7: % | F7: =Titles!A22 -> 2025 | G7: =Titles!A23 -> 2026 | H7: % | I7: =Titles!A22 -> 2025 | J7: =Titles!A23 -> 2026 | K7: %
A8: N.L. | C8: 51 | D8: 60 | E8: =IF(C8=D8,"-",IF((C8=0),"##",IF(ABS((D8/C8-1)*100)>=500,"##",(D8/C8-1)*100))) -> 17.647059 | F8: 41 | G8: 52 | H8: =IF(F8=G8,"-",IF((F8=0),"##",IF(ABS((G8/F8-1)*100)>=500,"##",(G8/F8-1)*100))) -> 26.829268 | I8: =C8+F8 -> 92 | J8: =D8+G8 -> 112 | K8: =IF(I8=J8,"-",IF((I8=0),"##",IF(ABS((J8/I8-1)*100)>=500,"##",(J8/I8-1)*100))) -> 21.73913
A9: P.E.I. | C9: 28 | D9: 26 | E9: =IF(C9=D9,"-",IF((C9=0),"##",IF(ABS((D9/C9-1)*100)>=500,"##",(D9/C9-1)*100))) -> -7.1428571 | F9: 238 | G9: 179 | H9: =IF(F9=G9,"-",IF((F9=0),"##",IF(ABS((G9/F9-1)*100)>=500,"##",(G9/F9-1)*100))) -> -24.789916 | I9: =C9+F9 -> 266 | J9: =D9+G9 -> 205 | K9: =IF(I9=J9,"-",IF((I9=0),"##",IF(ABS((J9/I9-1)*100)>=500,"##",(J9/I9-1)*100))) -> -22.932331
A10: N.S. | C10: 133 | D10: 140 | E10: =IF(C10=D10,"-",IF((C10=0),"##",IF(ABS((D10/C10-1)*100)>=500,"##",(D10/C10-1)*100))) -> 5.2631579 | F10: 919 | G10: 689 | H10: =IF(F10=G10,"-",IF((F10=0),"##",IF(ABS((G10/F10-1)*100)>=500,"##",(G10/F10-1)*100))) -> -25.027203 | I10: =C10+F10 -> 1052 | J10: =D10+G10 -> 829 | K10: =IF(I10=J10,"-",IF((I10=0),"##",IF(ABS((J10/I10-1)*100)>=500,"##",(J10/I10-1)*100))) -> -21.197719
A11: N.B. | C11: 53 | D11: 56 | E11: =IF(C11=D11,"-",IF((C11=0),"##",IF(ABS((D11/C11-1)*100)>=500,"##",(D11/C11-1)*100))) -> 5.6603774 | F11: 314 | G11: 496 | H11: =IF(F11=G11,"-",IF((F11=0),"##",IF(ABS((G11/F11-1)*100)>=500,"##",(G11/F11-1)*100))) -> 57.961783 | I11: =C11+F11 -> 367 | J11: =D11+G11 -> 552 | K11: =IF(I11=J11,"-",IF((I11=0),"##",IF(ABS((J11/I11-1)*100)>=500,"##",(J11/I11-1)*100))) -> 50.408719
A12: Atlantic | C12: =SUM(C8:C11) -> 265 | D12: =SUM(D8:D11) -> 282 | E12: =IF(C12=D12,"-",IF((C12=0),"##",IF(ABS((D12/C12-1)*100)>=500,"##",(D12/C12-1)*100))) -> 6.4150943 | F12: =SUM(F8:F11) -> 1512 | G12: =SUM(G8:G11) -> 1416 | H12: =IF(F12=G12,"-",IF((F12=0),"##",IF(ABS((G12/F12-1)*100)>=500,"##",(G12/F12-1)*100))) -> -6.3492063 | I12: =C12+F12 -> 1777 | J12: =D12+G12 -> 1698 | K12: =IF(I12=J12,"-",IF((I12=0),"##",IF(ABS((J12/I12-1)*100)>=500,"##",(J12/I12-1)*100))) -> -4.445695
A13: Que. | C13: 421 | D13: 500 | E13: =IF(C13=D13,"-",IF((C13=0),"##",IF(ABS((D13/C13-1)*100)>=500,"##",(D13/C13-1)*100))) -> 18.764846 | F13: 6157 | G13: 5052 | H13: =IF(F13=G13,"-",IF((F13=0),"##",IF(ABS((G13/F13-1)*100)>=500,"##",(G13/F13-1)*100))) -> -17.947052 | I13: =C13+F13 -> 6578 | J13: =D13+G13 -> 5552 | K13: =IF(I13=J13,"-",IF((I13=0),"##",IF(ABS((J13/I13-1)*100)>=500,"##",(J13/I13-1)*100))) -> -15.597446
A14: Ont. | C14: 1072 | D14: 937 | E14: =IF(C14=D14,"-",IF((C14=0),"##",IF(ABS((D14/C14-1)*100)>=500,"##",(D14/C14-1)*100))) -> -12.593284 | F14: 6905 | G14: 8183 | H14: =IF(F14=G14,"-",IF((F14=0),"##",IF(ABS((G14/F14-1)*100)>=500,"##",(G14/F14-1)*100))) -> 18.508327 | I14: =C14+F14 -> 7977 | J14: =D14+G14 -> 9120 | K14: =IF(I14=J14,"-",IF((I14=0),"##",IF(ABS((J14/I14-1)*100)>=500,"##",(J14/I14-1)*100))) -> 14.328695
A15: Man. | C15: 308 | D15: 260 | E15: =IF(C15=D15,"-",IF((C15=0),"##",IF(ABS((D15/C15-1)*100)>=500,"##",(D15/C15-1)*100))) -> -15.584416 | F15: 423 | G15: 667 | H15: =IF(F15=G15,"-",IF((F15=0),"##",IF(ABS((G15/F15-1)*100)>=500,"##",(G15/F15-1)*100))) -> 57.683215 | I15: =C15+F15 -> 731 | J15: =D15+G15 -> 927 | K15: =IF(I15=J15,"-",IF((I15=0),"##",IF(ABS((J15/I15-1)*100)>=500,"##",(J15/I15-1)*100))) -> 26.812585
A16: Sask. | C16: 160 | D16: 218 | E16: =IF(C16=D16,"-",IF((C16=0),"##",IF(ABS((D16/C16-1)*100)>=500,"##",(D16/C16-1)*100))) -> 36.25 | F16: 510 | G16: 349 | H16: =IF(F16=G16,"-",IF((F16=0),"##",IF(ABS((G16/F16-1)*100)>=500,"##",(G16/F16-1)*100))) -> -31.568627 | I16: =C16+F16 -> 670 | J16: =D16+G16 -> 567 | K16: =IF(I16=J16,"-",IF((I16=0),"##",IF(ABS((J16/I16-1)*100)>=500,"##",(J16/I16-1)*100))) -> -15.373134
A17: Alta. | C17: 2099 | D17: 1653 | E17: =IF(C17=D17,"-",IF((C17=0),"##",IF(ABS((D17/C17-1)*100)>=500,"##",(D17/C17-1)*100))) -> -21.248213 | F17: 5413 | G17: 4982 | H17: =IF(F17=G17,"-",IF((F17=0),"##",IF(ABS((G17/F17-1)*100)>=500,"##",(G17/F17-1)*100))) -> -7.962313 | I17: =C17+F17 -> 7512 | J17: =D17+G17 -> 6635 | K17: =IF(I17=J17,"-",IF((I17=0),"##",IF(ABS((J17/I17-1)*100)>=500,"##",(J17/I17-1)*100))) -> -11.674654
A18: Prairies | C18: =SUM(C15:C17) -> 2567 | D18: =SUM(D15:D17) -> 2131 | E18: =IF(C18=D18,"-",IF((C18=0),"##",IF(ABS((D18/C18-1)*100)>=500,"##",(D18/C18-1)*100))) -> -16.984807 | F18: =SUM(F15:F17) -> 6346 | G18: =SUM(G15:G17) -> 5998 | H18: =IF(F18=G18,"-",IF((F18=0),"##",IF(ABS((G18/F18-1)*100)>=500,"##",(G18/F18-1)*100))) -> -5.4837693 | I18: =C18+F18 -> 8913 | J18: =D18+G18 -> 8129 | K18: =IF(I18=J18,"-",IF((I18=0),"##",IF(ABS((J18/I18-1)*100)>=500,"##",(J18/I18-1)*100))) -> -8.7961405
A19: B.C. | C19: 490 | D19: 523 | E19: =IF(C19=D19,"-",IF((C19=0),"##",IF(ABS((D19/C19-1)*100)>=500,"##",(D19/C19-1)*100))) -> 6.7346939 | F19: 4642 | G19: 6952 | H19: =IF(F19=G19,"-",IF((F19=0),"##",IF(ABS((G19/F19-1)*100)>=500,"##",(G19/F19-1)*100))) -> 49.763033 | I19: =C19+F19 -> 5132 | J19: =D19+G19 -> 7475 | K19: =IF(I19=J19,"-",IF((I19=0),"##",IF(ABS((J19/I19-1)*100)>=500,"##",(J19/I19-1)*100))) -> 45.654716
A20: Canada | C20: =SUM(C12:C14,C18:C19) -> 4815 | D20: =SUM(D12:D14,D18:D19) -> 4373 | E20: =IF(C20=D20,"-",IF((C20=0),"##",IF(ABS((D20/C20-1)*100)>=500,"##",(D20/C20-1)*100))) -> -9.1796469 | F20: =SUM(F12:F14,F18:F19) -> 25562 | G20: =SUM(G12:G14,G18:G19) -> 27601 | H20: =IF(F20=G20,"-",IF((F20=0),"##",IF(ABS((G20/F20-1)*100)>=500,"##",(G20/F20-1)*100))) -> 7.9766841 | I20: =C20+F20 -> 30377 | J20: =D20+G20 -> 31974 | K20: =IF(I20=J20,"-",IF((I20=0),"##",IF(ABS((J20/I20-1)*100)>=500,"##",(J20/I20-1)*100))) -> 5.257267
A21: Metropolitan Areas
A23: Abbotsford-Mission | C23: 14 | D23: 13 | E23: =IF(C23=D23,"-",IF((C23=0),"##",IF(ABS((D23/C23-1)*100)>=500,"##",(D23/C23-1)*100))) -> -7.1428571 | F23: 432 | G23: 31 | H23: =IF(F23=G23,"-",IF((F23=0),"##",IF(ABS((G23/F23-1)*100)>=500,"##",(G23/F23-1)*100))) -> -92.824074 | I23: =C23+F23 -> 446 | J23: =D23+G23 -> 44 | K23: =IF(I23=J23,"-",IF((I23=0),"##",IF(ABS((J23/I23-1)*100)>=500,"##",(J23/I23-1)*100))) -> -90.134529
A24: Barrie | C24: 15 | D24: 22 | E24: =IF(C24=D24,"-",IF((C24=0),"##",IF(ABS((D24/C24-1)*100)>=500,"##",(D24/C24-1)*100))) -> 46.666667 | F24: 51 | G24: 36 | H24: =IF(F24=G24,"-",IF((F24=0),"##",IF(ABS((G24/F24-1)*100)>=500,"##",(G24/F24-1)*100))) -> -29.411765 | I24: =C24+F24 -> 66 | J24: =D24+G24 -> 58 | K24: =IF(I24=J24,"-",IF((I24=0),"##",IF(ABS((J24/I24-1)*100)>=500,"##",(J24/I24-1)*100))) -> -12.121212
A25: Belleville - Quinte West | C25: 16 | D25: 5 | E25: =IF(C25=D25,"-",IF((C25=0),"##",IF(ABS((D25/C25-1)*100)>=500,"##",(D25/C25-1)*100))) -> -68.75 | F25: 165 | G25: 4 | H25: =IF(F25=G25,"-",IF((F25=0),"##",IF(ABS((G25/F25-1)*100)>=500,"##",(G25/F25-1)*100))) -> -97.575758 | I25: =C25+F25 -> 181 | J25: =D25+G25 -> 9 | K25: =IF(I25=J25,"-",IF((I25=0),"##",IF(ABS((J25/I25-1)*100)>=500,"##",(J25/I25-1)*100))) -> -95.027624
A26: Brantford | C26: 14 | D26: 46 | E26: =IF(C26=D26,"-",IF((C26=0),"##",IF(ABS((D26/C26-1)*100)>=500,"##",(D26/C26-1)*100))) -> 228.57143 | F26: 242 | G26: 213 | H26: =IF(F26=G26,"-",IF((F26=0),"##",IF(ABS((G26/F26-1)*100)>=500,"##",(G26/F26-1)*100))) -> -11.983471 | I26: =C26+F26 -> 256 | J26: =D26+G26 -> 259 | K26: =IF(I26=J26,"-",IF((I26=0),"##",IF(ABS((J26/I26-1)*100)>=500,"##",(J26/I26-1)*100))) -> 1.171875
A27: Calgary | C27: 1052 | D27: 839 | E27: =IF(C27=D27,"-",IF((C27=0),"##",IF(ABS((D27/C27-1)*100)>=500,"##",(D27/C27-1)*100))) -> -20.247148 | F27: 2984 | G27: 2553 | H27: =IF(F27=G27,"-",IF((F27=0),"##",IF(ABS((G27/F27-1)*100)>=500,"##",(G27/F27-1)*100))) -> -14.4437 | I27: =C27+F27 -> 4036 | J27: =D27+G27 -> 3392 | K27: =IF(I27=J27,"-",IF((I27=0),"##",IF(ABS((J27/I27-1)*100)>=500,"##",(J27/I27-1)*100))) -> -15.956392
A28: Chilliwack | C28: 18 | D28: 14 | E28: =IF(C28=D28,"-",IF((C28=0),"##",IF(ABS((D28/C28-1)*100)>=500,"##",(D28/C28-1)*100))) -> -22.222222 | F28: 46 | G28: 17 | H28: =IF(F28=G28,"-",IF((F28=0),"##",IF(ABS((G28/F28-1)*100)>=500,"##",(G28/F28-1)*100))) -> -63.043478 | I28: =C28+F28 -> 64 | J28: =D28+G28 -> 31 | K28: =IF(I28=J28,"-",IF((I28=0),"##",IF(ABS((J28/I28-1)*100)>=500,"##",(J28/I28-1)*100))) -> -51.5625
A29: Drummondville | C29: 16 | D29: 29 | E29: =IF(C29=D29,"-",IF((C29=0),"##",IF(ABS((D29/C29-1)*100)>=500,"##",(D29/C29-1)*100))) -> 81.25 | F29: 85 | G29: 84 | H29: =IF(F29=G29,"-",IF((F29=0),"##",IF(ABS((G29/F29-1)*100)>=500,"##",(G29/F29-1)*100))) -> -1.1764706 | I29: =C29+F29 -> 101 | J29: =D29+G29 -> 113 | K29: =IF(I29=J29,"-",IF((I29=0),"##",IF(ABS((J29/I29-1)*100)>=500,"##",(J29/I29-1)*100))) -> 11.881188
A30: Edmonton | C30: 868 | D30: 629 | E30: =IF(C30=D30,"-",IF((C30=0),"##",IF(ABS((D30/C30-1)*100)>=500,"##",(D30/C30-1)*100))) -> -27.534562 | F30: 1821 | G30: 1850 | H30: =IF(F30=G30,"-",IF((F30=0),"##",IF(ABS((G30/F30-1)*100)>=500,"##",(G30/F30-1)*100))) -> 1.5925316 | I30: =C30+F30 -> 2689 | J30: =D30+G30 -> 2479 | K30: =IF(I30=J30,"-",IF((I30=0),"##",IF(ABS((J30/I30-1)*100)>=500,"##",(J30/I30-1)*100))) -> -7.8095946
A31: Fredericton | C31: 19 | D31: 14 | E31: =IF(C31=D31,"-",IF((C31=0),"##",IF(ABS((D31/C31-1)*100)>=500,"##",(D31/C31-1)*100))) -> -26.315789 | F31: 2 | G31: 92 | H31: =IF(F31=G31,"-",IF((F31=0),"##",IF(ABS((G31/F31-1)*100)>=500,"##",(G31/F31-1)*100))) -> ## | I31: =C31+F31 -> 21 | J31: =D31+G31 -> 106 | K31: =IF(I31=J31,"-",IF((I31=0),"##",IF(ABS((J31/I31-1)*100)>=500,"##",(J31/I31-1)*100))) -> 404.7619
A32: Greater/Grand Sudbury | C32: 2 | D32: 5 | E32: =IF(C32=D32,"-",IF((C32=0),"##",IF(ABS((D32/C32-1)*100)>=500,"##",(D32/C32-1)*100))) -> 150 | F32: 0 | G32: 7 | H32: =IF(F32=G32,"-",IF((F32=0),"##",IF(ABS((G32/F32-1)*100)>=500,"##",(G32/F32-1)*100))) -> ## | I32: =C32+F32 -> 2 | J32: =D32+G32 -> 12 | K32: =IF(I32=J32,"-",IF((I32=0),"##",IF(ABS((J32/I32-1)*100)>=500,"##",(J32/I32-1)*100))) -> ##
A33: Guelph | C33: 1 | D33: 3 | E33: =IF(C33=D33,"-",IF((C33=0),"##",IF(ABS((D33/C33-1)*100)>=500,"##",(D33/C33-1)*100))) -> 200 | F33: 1 | G33: 19 | H33: =IF(F33=G33,"-",IF((F33=0),"##",IF(ABS((G33/F33-1)*100)>=500,"##",(G33/F33-1)*100))) -> ## | I33: =C33+F33 -> 2 | J33: =D33+G33 -> 22 | K33: =IF(I33=J33,"-",IF((I33=0),"##",IF(ABS((J33/I33-1)*100)>=500,"##",(J33/I33-1)*100))) -> ##
A34: Halifax | C34: 91 | D34: 77 | E34: =IF(C34=D34,"-",IF((C34=0),"##",IF(ABS((D34/C34-1)*100)>=500,"##",(D34/C34-1)*100))) -> -15.384615 | F34: 861 | G34: 604 | H34: =IF(F34=G34,"-",IF((F34=0),"##",IF(ABS((G34/F34-1)*100)>=500,"##",(G34/F34-1)*100))) -> -29.849013 | I34: =C34+F34 -> 952 | J34: =D34+G34 -> 681 | K34: =IF(I34=J34,"-",IF((I34=0),"##",IF(ABS((J34/I34-1)*100)>=500,"##",(J34/I34-1)*100))) -> -28.466387
... A45: Oshawa | C45: 15 | D45: 58 | E45: =IF(C45=D45,"-",IF((C45=0),"##",IF(ABS((D45/C45-1)*100)>=500,"##",(D45/C45-1)*100))) -> 286.66667 | F45: 4 | G45: 45 | H45: =IF(F45=G45,"-",IF((F45=0),"##",IF(ABS((G45/F45-1)*100)>=500,"##",(G45/F45-1)*100))) -> ## | I45: =C45+F45 -> 19 | J45: =D45+G45 -> 103 | K45: =IF(I45=J45,"-",IF((I45=0),"##",IF(ABS((J45/I45-1)*100)>=500,"##",(J45/I45-1)*100))) -> 442.10526
A46: Ottawa-Gatineau | C46: =+SUM(C47+C48) -> 246 | D46: =+SUM(D47+D48) -> 215 | E46: =IF(C46=D46,"-",IF((C46=0),"##",IF(ABS((D46/C46-1)*100)>=500,"##",(D46/C46-1)*100))) -> -12.601626 | F46: =+SUM(F47+F48) -> 1637 | G46: =+SUM(G47+G48) -> 1680 | H46: =IF(F46=G46,"-",IF((F46=0),"##",IF(ABS((G46/F46-1)*100)>=500,"##",(G46/F46-1)*100))) -> 2.6267563 | I46: =C46+F46 -> 1883 | J46: =D46+G46 -> 1895 | K46: =IF(I46=J46,"-",IF((I46=0),"##",IF(ABS((J46/I46-1)*100)>=500,"##",(J46/I46-1)*100))) -> 0.63728093
A47: Gatineau | C47: 30 | D47: 55 | E47: =IF(C47=D47,"-",IF((C47=0),"##",IF(ABS((D47/C47-1)*100)>=500,"##",(D47/C47-1)*100))) -> 83.333333 | F47: 401 | G47: 339 | H47: =IF(F47=G47,"-",IF((F47=0),"##",IF(ABS((G47/F47-1)*100)>=500,"##",(G47/F47-1)*100))) -> -15.461347 | I47: =C47+F47 -> 431 | J47: =D47+G47 -> 394 | K47: =IF(I47=J47,"-",IF((I47=0),"##",IF(ABS((J47/I47-1)*100)>=500,"##",(J47/I47-1)*100))) -> -8.5846868
A48: Ottawa | C48: 216 | D48: 160 | E48: =IF(C48=D48,"-",IF((C48=0),"##",IF(ABS((D48/C48-1)*100)>=500,"##",(D48/C48-1)*100))) -> -25.925926 | F48: 1236 | G48: 1341 | H48: =IF(F48=G48,"-",IF((F48=0),"##",IF(ABS((G48/F48-1)*100)>=500,"##",(G48/F48-1)*100))) -> 8.4951456 | I48: =C48+F48 -> 1452 | J48: =D48+G48 -> 1501 | K48: =IF(I48=J48,"-",IF((I48=0),"##",IF(ABS((J48/I48-1)*100)>=500,"##",(J48/I48-1)*100))) -> 3.3746556
A49: Peterborough | C49: 15 | D49: 7 | E49: =IF(C49=D49,"-",IF((C49=0),"##",IF(ABS((D49/C49-1)*100)>=500,"##",(D49/C49-1)*100))) -> -53.333333 | F49: 1 | G49: 0 | H49: =IF(F49=G49,"-",IF((F49=0),"##",IF(ABS((G49/F49-1)*100)>=500,"##",(G49/F49-1)*100))) -> -100 | I49: =C49+F49 -> 16 | J49: =D49+G49 -> 7 | K49: =IF(I49=J49,"-",IF((I49=0),"##",IF(ABS((J49/I49-1)*100)>=500,"##",(J49/I49-1)*100))) -> -56.25
A50: Québec | C50: 69 | D50: 97 | E50: =IF(C50=D50,"-",IF((C50=0),"##",IF(ABS((D50/C50-1)*100)>=500,"##",(D50/C50-1)*100))) -> 40.57971 | F50: 981 | G50: 894 | H50: =IF(F50=G50,"-",IF((F50=0),"##",IF(ABS((G50/F50-1)*100)>=500,"##",(G50/F50-1)*100))) -> -8.8685015 | I50: =C50+F50 -> 1050 | J50: =D50+G50 -> 991 | K50: =IF(I50=J50,"-",IF((I50=0),"##",IF(ABS((J50/I50-1)*100)>=500,"##",(J50/I50-1)*100))) -> -5.6190476
A51: Red Deer | C51: 23 | D51: 12 | E51: =IF(C51=D51,"-",IF((C51=0),"##",IF(ABS((D51/C51-1)*100)>=500,"##",(D51/C51-1)*100))) -> -47.826087 | F51: 14 | G51: 17 | H51: =IF(F51=G51,"-",IF((F51=0),"##",IF(ABS((G51/F51-1)*100)>=500,"##",(G51/F51-1)*100))) -> 21.428571 | I51: =C51+F51 -> 37 | J51: =D51+G51 -> 29 | K51: =IF(I51=J51,"-",IF((I51=0),"##",IF(ABS((J51/I51-1)*100)>=500,"##",(J51/I51-1)*100))) -> -21.621622
A52: Regina | C52: 39 | D52: 70 | E52: =IF(C52=D52,"-",IF((C52=0),"##",IF(ABS((D52/C52-1)*100)>=500,"##",(D52/C52-1)*100))) -> 79.487179 | F52: 398 | G52: 70 | H52: =IF(F52=G52,"-",IF((F52=0),"##",IF(ABS((G52/F52-1)*100)>=500,"##",(G52/F52-1)*100))) -> -82.41206 | I52: =C52+F52 -> 437 | J52: =D52+G52 -> 140 | K52: =IF(I52=J52,"-",IF((I52=0),"##",IF(ABS((J52/I52-1)*100)>=500,"##",(J52/I52-1)*100))) -> -67.963387
...

Sheet Table 3
A1: Table 3
A2: Dwelling Starts in Urban Centres and Canada, Seasonally Adjusted at Annual Rates
E5: Centres 10,000 Population and Over1
A7: Period | D7: Single- | E7: All | F7: Total | G7: Other | H7: Canada
D8: Detached | E8: Others | G8: Areas
A11: 20242 | D11: 44383 | E11: 183314 | F11: 227697 | G11: 17423 | H11: 245120
A12: 20252 | D12: 41851 | E12: 199320 | F12: 241171 | G12: 17857 | H12: 259028
A13: =Titles!A22 -> 2025 | B13: 1st Q. | D13: 42990 | E13: 176150 | F13: 219140 | G13: 10888 | H13: =IF(SUM(F13,G13)=0,"",SUM(F13,G13)) -> 230028
B14: 2nd Q. | D14: 43587 | E14: 210123 | F14: 253710 | G14: 22333 | H14: =IF(SUM(F14,G14)=0,"",SUM(F14,G14)) -> 276043
B15: 3rd Q. | D15: 40872 | E15: 207772 | F15: 248644 | G15: 23990 | H15: =IF(SUM(F15,G15)=0,"",SUM(F15,G15)) -> 272634
B16: 4th Q. | D16: 40248 | E16: 203295 | F16: 243543 | G16: 13438 | H16: =IF(SUM(F16,G16)=0,"",SUM(F16,G16)) -> 256981
A18: =Titles!A23 -> 2026 | B18: 1st Q.
B19: 2nd Q.
B20: 3rd Q.
B21: 4th Q.
A22: =Titles!A22 -> 2025 | B22: January | D22: 44028 | E22: 176269 | F22: 220297 | G22: 13533 | H22: =IF(SUM(F22,G22)=0,"",SUM(F22,G22)) -> 233830
B23: February | D23: 42695 | E23: 166594 | F23: 209289 | G23: 13159 | H23: =IF(SUM(F23,G23)=0,"",SUM(F23,G23)) -> 222448
B24: March | D24: 42423 | E24: 159826 | F24: 202249 | G24: 12245 | H24: =IF(SUM(F24,G24)=0,"",SUM(F24,G24)) -> 214494
B25: April | D25: 44333 | E25: 216960 | F25: 261293 | G25: 20533 | H25: =IF(SUM(F25,G25)=0,"",SUM(F25,G25)) -> 281826
B26: May | D26: 42278 | E26: 215415 | F26: 257693 | G26: 21008 | H26: =IF(SUM(F26,G26)=0,"",SUM(F26,G26)) -> 278701
B27: June | D27: 42939 | E27: 219862 | F27: 262801 | G27: 21364 | H27: =IF(SUM(F27,G27)=0,"",SUM(F27,G27)) -> 284165
B28: July | D28: 42049 | E28: 228167 | F28: 270216 | G28: 23661 | H28: =IF(SUM(F28,G28)=0,"",SUM(F28,G28)) -> 293877
B29: August | D29: 40179 | E29: 180076 | F29: 220255 | G29: 24018 | H29: =IF(SUM(F29,G29)=0,"",SUM(F29,G29)) -> 244273
B30: September | D30: 41587 | E30: 215708 | F30: 257295 | G30: 23531 | H30: =IF(SUM(F30,G30)=0,"",SUM(F30,G30)) -> 280826
B31: October | D31: 41457 | E31: 176547 | F31: 218004 | G31: 13336 | H31: =IF(SUM(F31,G31)=0,"",SUM(F31,G31)) -> 231340
B32: November | D32: 40022 | E32: 199666 | F32: 239688 | G32: 12761 | H32: =IF(SUM(F32,G32)=0,"",SUM(F32,G32)) -> 252449
B33: December | D33: 39276 | E33: 229097 | F33: 268373 | G33: 11992 | H33: =IF(SUM(F33,G33)=0,"",SUM(F33,G33)) -> 280365
A35: =Titles!A23 -> 2026 | B35: January | D35: 41656 | E35: 178323 | F35: 219979 | G35: 20169 | H35: =IF(SUM(F35,G35)=0,"",SUM(F35,G35)) -> 240148
B36: February | D36: 38190 | E36: 192310 | F36: 230500 | G36: 20400 | H36: =IF(SUM(F36,G36)=0,"",SUM(F36,G36)) -> 250900
B37: March | H37: =IF(SUM(F37,G37)=0,"",SUM(F37,G37))
B38: April | H38: =IF(SUM(F38,G38)=0,"",SUM(F38,G38))
B39: May | H39: =IF(SUM(F39,G39)=0,"",SUM(F39,G39))
B40: June | H40: =IF(SUM(F40,G40)=0,"",SUM(F40,G40))
B41: July | H41: =IF(SUM(F41,G41)=0,"",SUM(F41,G41))
B42: August | H42: =IF(SUM(F42,G42)=0,"",SUM(F42,G42))
B43: September | H43: =IF(SUM(F43,G43)=0,"",SUM(F43,G43))
B44: October | H44: =IF(SUM(F44,G44)=0,"",SUM(F44,G44))
B45: November | H45: =IF(SUM(F45,G45)=0,"",SUM(F45,G45))
B46: December | H46: =IF(SUM(F46,G46)=0,"",SUM(F46,G46))
A47: =Titles!$A$12 -> 1 Data for 2023, 2024 and 2025 based on 2021 Census Definitions.
...

Sheet Table 4
A1: Table 4
A2: Dwelling Starts in Urban Centres1, by Region, Seasonally Adjusted at Annual Rates
A6: Period | E6: Atlantic | F6: Québec | G6: Ontario | H6: Prairies | I6: B. C. | J6: Total
A7: 2024 2 | E7: 13998 | F7: 41221 | G7: 72118 | H7: 56787 | I7: 43573 | J7: 227971
A8: 2025 2 | E8: 16856 | F8: 54220 | G8: 62561 | H8: 66002 | I8: 41532 | J8: 241171
A10: Single-Detached | B10: 2024 | C10: 3rd Q. | E10: 3381 | F10: 4055 | G10: 13165 | H10: 18849 | I10: 4482 | J10: =SUM(E10:I10) -> 43932
B11: 2024 | C11: 4th Q. | E11: 3634 | F11: 5633 | G11: 12234 | H11: 20431 | I11: 4355 | J11: =SUM(E11:I11) -> 46287
A12: All Others | B12: 2024 | C12: 3rd Q. | E12: 9055 | F12: 36795 | G12: 60688 | H12: 40007 | I12: 35942 | J12: =SUM(E12:I12) -> 182487
B13: 2024 | C13: 4th Q. | E13: 8826 | F13: 41331 | G13: 48693 | H13: 42316 | I13: 37543 | J13: =SUM(E13:I13) -> 178709
A14: Total | B14: 2024 | C14: 3rd Q. | E14: =SUM(E10,E12) -> 12436 | F14: =SUM(F10,F12) -> 40850 | G14: =SUM(G10,G12) -> 73853 | H14: =SUM(H10,H12) -> 58856 | I14: =SUM(I10,I12) -> 40424 | J14: =SUM(E14:I14) -> 226419
B15: 2024 | C15: 4th Q. | E15: =SUM(E11,E13) -> 12460 | F15: =SUM(F11,F13) -> 46964 | G15: =SUM(G11,G13) -> 60927 | H15: =SUM(H11,H13) -> 62747 | I15: =SUM(I11,I13) -> 41898 | J15: =SUM(E15:I15) -> 224996
A17: Single-Detached | B17: 2025 | C17: 3rd Q. | E17: 3714 | F17: 4830 | G17: 9362 | H17: 18891 | I17: 4075 | J17: =SUM(E17:I17) -> 40872
B18: 2025 | C18: 4th Q. | E18: 3814 | F18: 5076 | G18: 10285 | H18: 16603 | I18: 4470 | J18: =SUM(E18:I18) -> 40248
A19: All Others | B19: 2025 | C19: 3rd Q. | E19: 14594 | F19: 45945 | G19: 62307 | H19: 45122 | I19: 39804 | J19: =SUM(E19:I19) -> 207772
B20: 2025 | C20: 4th Q. | E20: 14179 | F20: 56761 | G20: 53537 | H20: 45370 | I20: 33448 | J20: =SUM(E20:I20) -> 203295
A21: Total | B21: 2025 | C21: 3rd Q. | E21: =SUM(E17,E19) -> 18308 | F21: =SUM(F17,F19) -> 50775 | G21: =SUM(G17,G19) -> 71669 | H21: =SUM(H17,H19) -> 64013 | I21: =SUM(I17,I19) -> 43879 | J21: =SUM(E21:I21) -> 248644
B22: 2025 | C22: 4th Q. | E22: =SUM(E18,E20) -> 17993 | F22: =SUM(F18,F20) -> 61837 | G22: =SUM(G18,G20) -> 63822 | H22: =SUM(H18,H20) -> 61973 | I22: =SUM(I18,I20) -> 37918 | J22: =SUM(E22:I22) -> 243543
A24: Single-Detached | B24: 2024 | C24: Dec. | E24: 3378 | F24: 5392 | G24: 12321 | H24: 19478 | I24: 4274 | J24: =SUM(E24:I24) -> 44843
B25: 2025 | C25: Jan | E25: 3342 | F25: 5037 | G25: 10692 | H25: 20351 | I25: 4606 | J25: =SUM(E25:I25) -> 44028
B26: 2025 | C26: Feb. | E26: 2763 | F26: 4752 | G26: 9725 | H26: 21687 | I26: 3768 | J26: =SUM(E26:I26) -> 42695
A27: All Others | B27: 2024 | C27: Dec. | E27: 9252 | F27: 36542 | G27: 50581 | H27: 32405 | I27: 41135 | J27: =SUM(E27:I27) -> 169915
B28: 2025 | C28: Jan | E28: 9135 | F28: 53567 | G28: 47011 | H28: 34411 | I28: 32145 | J28: =SUM(E28:I28) -> 176269
B29: 2025 | C29: Feb. | E29: 9594 | F29: 43281 | G29: 46608 | H29: 43296 | I29: 23815 | J29: =SUM(E29:I29) -> 166594
A30: Total | B30: 2024 | C30: Dec. | E30: =SUM(E24,E27) -> 12630 | F30: =SUM(F24,F27) -> 41934 | G30: =SUM(G24,G27) -> 62902 | H30: =SUM(H24,H27) -> 51883 | I30: =SUM(I24,I27) -> 45409 | J30: =SUM(J24,J27) -> 214758
B31: 2025 | C31: Jan | E31: =SUM(E25,E28) -> 12477 | F31: =SUM(F25,F28) -> 58604 | G31: =SUM(G25,G28) -> 57703 | H31: =SUM(H25,H28) -> 54762 | I31: =SUM(I25,I28) -> 36751 | J31: =SUM(J25,J28) -> 220297
B32: 2025 | C32: Feb. | E32: =SUM(E26,E29) -> 12357 | F32: =SUM(F26,F29) -> 48033 | G32: =SUM(G26,G29) -> 56333 | H32: =SUM(H26,H29) -> 64983 | I32: =SUM(I26,I29) -> 27583 | J32: =SUM(J26,J29) -> 209289
A34: Single-Detached | B34: 2025 | C34: Dec. | E34: 3821 | F34: 4645 | G34: 9585 | H34: 16729 | I34: 4496 | J34: =SUM(E34:I34) -> 39276
B35: 2026 | C35: Jan | E35: 4084 | F35: 5893 | G35: 10788 | H35: 16112 | I35: 4779 | J35: =SUM(E35:I35) -> 41656
B36: 2026 | C36: Feb. | E36: 2366 | F36: 5208 | G36: 7583 | H36: 18885 | I36: 4148 | J36: =SUM(E36:I36) -> 38190
A37: All Others | B37: 2025 | C37: Dec. | E37: 13674 | F37: 55928 | G37: 84266 | H37: 33392 | I37: 41837 | J37: =SUM(E37:I37) -> 229097
B38: 2026 | C38: Jan | E38: 8841 | F38: 34591 | G38: 52440 | H38: 35856 | I38: 46595 | J38: =SUM(E38:I38) -> 178323
B39: 2026 | C39: Feb. | E39: 10328 | F39: 49939 | G39: 56067 | H39: 37422 | I39: 38554 | J39: =SUM(E39:I39) -> 192310
A40: Total | B40: 2025 | C40: Dec. | E40: =SUM(E34,E37) -> 17495 | F40: =SUM(F34,F37) -> 60573 | G40: =SUM(G34,G37) -> 93851 | H40: =SUM(H34,H37) -> 50121 | I40: =SUM(I34,I37) -> 46333 | J40: =SUM(J34,J37) -> 268373
B41: 2026 | C41: Jan | E41: =SUM(E35,E38) -> 12925 | F41: =SUM(F35,F38) -> 40484 | G41: =SUM(G35,G38) -> 63228 | H41: =SUM(H35,H38) -> 51968 | I41: =SUM(I35,I38) -> 51374 | J41: =SUM(J35,J38) -> 219979
B42: 2026 | C42: Feb. | E42: =SUM(E36,E39) -> 12694 | F42: =SUM(F36,F39) -> 55147 | G42: =SUM(G36,G39) -> 63650 | H42: =SUM(H36,H39) -> 56307 | I42: =SUM(I36,I39) -> 42702 | J42: =SUM(J36,J39) -> 230500
A43: =Titles!$A$12 -> 1 Data for 2023, 2024 and 2025 based on 2021 Census Definitions.
A44: 2 Data are Actual Dwelling Starts.
A45: =Titles!$A$10 -> Source: CMHC Starts and Completion Survey, Market Absorption Survey

Sheet Table 5
A1: Table 5
A2: Dwelling Starts in Urban Centres1, by Region, Seasonally Adjusted at Annual Rates
A6: Period | D6: Atlantic | E6: Québec | F6: Ontario | G6: Prairies | H6: B. C. | I6: Total
A7: 2024 2 | D7: 13998 | E7: 41221 | F7: 72118 | G7: 56787 | H7: 43573 | I7: 227971
A8: 2025 2 | D8: 16856 | E8: 54220 | F8: 62561 | G8: 66002 | H8: 41532 | I8: 241171
A9: 2024 | B9: 1st Q. | D9: 15603 | E9: 35511 | F9: 78452 | G9: 51274 | H9: 48329 | I9: 229169
B10: 2nd Q. | D10: 15544 | E10: 40155 | F10: 73297 | G10: 54090 | H10: 41531 | I10: 224617
B11: 3rd Q. | D11: 12436 | E11: 40850 | F11: 73853 | G11: 58856 | H11: 40424 | I11: 226419
B12: 4th Q. | D12: 12460 | E12: 46964 | F12: 60927 | G12: 62747 | H12: 41898 | I12: 224996
A13: 2025 | B13: 1st Q. | D13: 13912 | E13: 53252 | F13: 49916 | G13: 63407 | H13: 38653 | I13: 219140
B14: 2nd Q. | D14: 17106 | E14: 50623 | F14: 65372 | G14: 75031 | H14: 45578 | I14: 253710
B15: 3rd Q. | D15: 18308 | E15: 50775 | F15: 71669 | G15: 64013 | H15: 43879 | I15: 248644
B16: 4th Q. | D16: 17993 | E16: 61837 | F16: 63822 | G16: 61973 | H16: 37918 | I16: 243543
A17: 2026 | B17: 1st Q.
B18: 2nd Q.
B19: 3rd Q.
B20: 4th Q.
A21: 2024 | B21: January | D21: 12042 | E21: 36988 | F21: 79331 | G21: 47909 | H21: 28841 | I21: =IF(SUM(D21:H21)=0,"",SUM(D21:H21)) -> 205111
B22: February | D22: 17841 | E22: 38179 | F22: 85766 | G22: 54594 | H22: 44738 | I22: =IF(SUM(D22:H22)=0,"",SUM(D22:H22)) -> 241118
B23: March | D23: 10187 | E23: 34759 | F23: 70319 | G23: 46760 | H23: 58913 | I23: =IF(SUM(D23:H23)=0,"",SUM(D23:H23)) -> 220938
B24: April | D24: 11509 | E24: 28887 | F24: 71474 | G24: 56966 | H24: 52864 | I24: =IF(SUM(D24:H24)=0,"",SUM(D24:H24)) -> 221700
B25: May | D25: 17580 | E25: 41384 | F25: 85087 | G25: 52476 | H25: 44376 | I25: =IF(SUM(D25:H25)=0,"",SUM(D25:H25)) -> 240903
B26: June | D26: 17805 | E26: 52287 | F26: 64541 | G26: 54836 | H26: 38869 | I26: =IF(SUM(D26:H26)=0,"",SUM(D26:H26)) -> 228338
B27: July | D27: 12427 | E27: 35630 | F27: 103803 | G27: 65410 | H27: 45906 | I27: =IF(SUM(D27:H27)=0,"",SUM(D27:H27)) -> 263176
B28: August | D28: 13028 | E28: 43471 | F28: 58071 | G28: 56437 | H28: 31467 | I28: =IF(SUM(D28:H28)=0,"",SUM(D28:H28)) -> 202474
B29: September | D29: 12981 | E29: 43859 | F29: 61570 | G29: 55173 | H29: 40645 | I29: =IF(SUM(D29:H29)=0,"",SUM(D29:H29)) -> 214228
B30: October | D30: 11334 | E30: 40245 | F30: 63184 | G30: 65144 | H30: 41409 | I30: =IF(SUM(D30:H30)=0,"",SUM(D30:H30)) -> 221316
B31: November | D31: 13185 | E31: 49794 | F31: 58137 | G31: 72289 | H31: 49432 | I31: =IF(SUM(D31:H31)=0,"",SUM(D31:H31)) -> 242837
B32: December | D32: 12630 | E32: 41934 | F32: 62902 | G32: 51883 | H32: 45409 | I32: =IF(SUM(D32:H32)=0,"",SUM(D32:H32)) -> 214758
A33: 2025 | B33: January | D33: 12477 | E33: 58604 | F33: 57703 | G33: 54762 | H33: 36751 | I33: =IF(SUM(D33:H33)=0,"",SUM(D33:H33)) -> 220297
B34: February | D34: 12357 | E34: 48033 | F34: 56333 | G34: 64983 | H34: 27583 | I34: =IF(SUM(D34:H34)=0,"",SUM(D34:H34)) -> 209289
B35: March | D35: 12390 | E35: 54864 | F35: 38451 | G35: 67352 | H35: 29192 | I35: =IF(SUM(D35:H35)=0,"",SUM(D35:H35)) -> 202249
B36: April | D36: 18561 | E36: 49689 | F36: 65839 | G36: 75097 | H36: 52107 | I36: =IF(SUM(D36:H36)=0,"",SUM(D36:H36)) -> 261293
B37: May | D37: 16625 | E37: 55429 | F37: 68491 | G37: 80625 | H37: 36523 | I37: =IF(SUM(D37:H37)=0,"",SUM(D37:H37)) -> 257693
B38: June | D38: 16740 | E38: 51678 | F38: 58984 | G38: 71010 | H38: 64389 | I38: =IF(SUM(D38:H38)=0,"",SUM(D38:H38)) -> 262801
B39: July | D39: 29395 | E39: 54225 | F39: 72602 | G39: 59759 | H39: 54235 | I39: =IF(SUM(D39:H39)=0,"",SUM(D39:H39)) -> 270216
B40: August | D40: 16718 | E40: 46271 | F40: 54547 | G40: 59046 | H40: 43673 | I40: =IF(SUM(D40:H40)=0,"",SUM(D40:H40)) -> 220255
B41: September | D41: 12664 | E41: 51279 | F41: 86441 | G41: 72759 | H41: 34152 | I41: =IF(SUM(D41:H41)=0,"",SUM(D41:H41)) -> 257295
B42: October | D42: 15622 | E42: 56593 | F42: 41974 | G42: 69904 | H42: 33911 | I42: =IF(SUM(D42:H42)=0,"",SUM(D42:H42)) -> 218004
B43: November | D43: 20651 | E43: 56690 | F43: 54499 | G43: 68337 | H43: 39511 | I43: =IF(SUM(D43:H43)=0,"",SUM(D43:H43)) -> 239688
...

Sheet Table 6
A1: Table 6
A2: Dwelling Starts in Urban Centres1, Atlantic Provinces, Seasonally Adjusted at Annual Rates
A5: Period | D5: Newfoundland | E5: Prince Edward | F5: Nova Scotia | G5: New Brunswick | H5: Total
E6: Island
A9: 2024 2 | D9: 1014 | E9: 1334 | F9: 6663 | G9: 4987 | H9: 13998
A10: 2025 2 | D10: 1131 | E10: 1276 | F10: 8732 | G10: 5717 | H10: 16856
A11: 2024 | B11: 1st Q. | D11: 898 | E11: 1520 | F11: 8554 | G11: 4631 | H11: 15603
B12: 2nd Q. | D12: 896 | E12: 976 | F12: 8696 | G12: 4976 | H12: 15544
B13: 3rd Q. | D13: 1098 | E13: 1754 | F13: 4391 | G13: 5193 | H13: 12436
B14: 4th Q. | D14: 1152 | E14: 949 | F14: 5061 | G14: 5298 | H14: 12460
A15: 2025 | B15: 1st Q. | D15: 1001 | E15: 1402 | F15: 6727 | G15: 4782 | H15: 13912
B16: 2nd Q. | D16: 1197 | E16: 1123 | F16: 9622 | G16: 5164 | H16: 17106
B17: 3rd Q. | D17: 1077 | E17: 1845 | F17: 9835 | G17: 5551 | H17: 18308
B18: 4th Q. | D18: 1203 | E18: 731 | F18: 8670 | G18: 7389 | H18: 17993
A19: 2026 | B19: 1st Q.
B20: 2nd Q.
B21: 3rd Q.
B22: 4th Q.
A23: 2024 | B23: January | D23: 1259 | E23: 1092 | F23: 6029 | G23: 3662 | H23: =IF(SUM(C23:G23)=0,"",SUM(C23:G23)) -> 12042
B24: February | D24: 730 | E24: 287 | F24: 12078 | G24: 4746 | H24: =IF(SUM(C24:G24)=0,"",SUM(C24:G24)) -> 17841
B25: March | D25: 349 | E25: 791 | F25: 7564 | G25: 1483 | H25: =IF(SUM(C25:G25)=0,"",SUM(C25:G25)) -> 10187
B26: April | D26: 809 | E26: 231 | F26: 7179 | G26: 3290 | H26: =IF(SUM(C26:G26)=0,"",SUM(C26:G26)) -> 11509
B27: May | D27: 708 | E27: 1544 | F27: 8103 | G27: 7225 | H27: =IF(SUM(C27:G27)=0,"",SUM(C27:G27)) -> 17580
B28: June | D28: 1152 | E28: 601 | F28: 10873 | G28: 5179 | H28: =IF(SUM(C28:G28)=0,"",SUM(C28:G28)) -> 17805
B29: July | D29: 940 | E29: 2173 | F29: 5559 | G29: 3755 | H29: =IF(SUM(C29:G29)=0,"",SUM(C29:G29)) -> 12427
B30: August | D30: 1200 | E30: 597 | F30: 3380 | G30: 7851 | H30: =IF(SUM(C30:G30)=0,"",SUM(C30:G30)) -> 13028
B31: September | D31: 1043 | E31: 400 | F31: 4141 | G31: 7397 | H31: =IF(SUM(C31:G31)=0,"",SUM(C31:G31)) -> 12981
B32: October | D32: 1292 | E32: 1272 | F32: 4171 | G32: 4599 | H32: =IF(SUM(C32:G32)=0,"",SUM(C32:G32)) -> 11334
B33: November | D33: 1407 | E33: 243 | F33: 5696 | G33: 5839 | H33: =IF(SUM(C33:G33)=0,"",SUM(C33:G33)) -> 13185
B34: December | D34: 1099 | E34: 1272 | F34: 5403 | G34: 4856 | H34: =IF(SUM(C34:G34)=0,"",SUM(C34:G34)) -> 12630
A35: 2025 | B35: January | D35: 953 | E35: 2466 | F35: 7380 | G35: 1678 | H35: =IF(SUM(C35:G35)=0,"",SUM(C35:G35)) -> 12477
B36: February | D36: 951 | E36: 869 | F36: 6239 | G36: 4298 | H36: =IF(SUM(C36:G36)=0,"",SUM(C36:G36)) -> 12357
B37: March | D37: 911 | E37: 364 | F37: 6168 | G37: 4947 | H37: =IF(SUM(C37:G37)=0,"",SUM(C37:G37)) -> 12390
B38: April | D38: 1504 | E38: 1983 | F38: 12527 | G38: 2547 | H38: =IF(SUM(C38:G38)=0,"",SUM(C38:G38)) -> 18561
B39: May | D39: 1127 | E39: 392 | F39: 8673 | G39: 6433 | H39: =IF(SUM(C39:G39)=0,"",SUM(C39:G39)) -> 16625
B40: June | D40: 1085 | E40: 545 | F40: 7949 | G40: 7161 | H40: =IF(SUM(C40:G40)=0,"",SUM(C40:G40)) -> 16740
B41: July | D41: 1164 | E41: 2708 | F41: 16805 | G41: 8718 | H41: =IF(SUM(C41:G41)=0,"",SUM(C41:G41)) -> 29395
B42: August | D42: 836 | E42: 2306 | F42: 6875 | G42: 6701 | H42: =IF(SUM(C42:G42)=0,"",SUM(C42:G42)) -> 16718
B43: September | D43: 1127 | E43: 899 | F43: 5792 | G43: 4846 | H43: =IF(SUM(C43:G43)=0,"",SUM(C43:G43)) -> 12664
B44: October | D44: 1175 | E44: 646 | F44: 8311 | G44: 5490 | H44: =IF(SUM(C44:G44)=0,"",SUM(C44:G44)) -> 15622
...

Sheet Table 7
A1: Table 7
A2: Dwelling Starts in Urban Centres1, Prairie Provinces, Seasonally Adjusted at Annual Rates
A6: Period | D6: Manitoba | E6: Saskatchewan | F6: Alberta | G6: Total
A7: 2024 2 | D7: 6164 | E7: 3991 | F7: 46632 | G7: 56787
A8: 2025 2 | D8: 7139 | E8: 5679 | F8: 53184 | G8: 66002
A9: 2024 | B9: 1st Q. | D9: 4372 | E9: 3149 | F9: 43753 | G9: 51274
B10: 2nd Q. | D10: 6184 | E10: 3212 | F10: 44694 | G10: 54090
B11: 3rd Q. | D11: 7007 | E11: 5379 | F11: 46470 | G11: 58856
B12: 4th Q. | D12: 7106 | E12: 4272 | F12: 51369 | G12: 62747
A13: 2025 | B13: 1st Q. | D13: 5804 | E13: 5841 | F13: 51762 | G13: 63407
B14: 2nd Q. | D14: 6426 | E14: 5752 | F14: 62853 | G14: 75031
B15: 3rd Q. | D15: 8569 | E15: 5900 | F15: 49544 | G15: 64013
B16: 4th Q. | D16: 7762 | E16: 5119 | F16: 49092 | G16: 61973
A17: 2026 | B17: 1st Q.
B18: 2nd Q.
B19: 3rd Q.
B20: 4th Q.
A21: 2024 | B21: January | D21: 3909 | E21: 3164 | F21: 40836 | G21: =IF(SUM(B21:F21)=0,"",SUM(B21:F21)) -> 47909
B22: February | D22: 4297 | E22: 2798 | F22: 47499 | G22: =IF(SUM(B22:F22)=0,"",SUM(B22:F22)) -> 54594
B23: March | D23: 4692 | E23: 3067 | F23: 39001 | G23: =IF(SUM(B23:F23)=0,"",SUM(B23:F23)) -> 46760
B24: April | D24: 7551 | E24: 3959 | F24: 45456 | G24: =IF(SUM(B24:F24)=0,"",SUM(B24:F24)) -> 56966
B25: May | D25: 2701 | E25: 1633 | F25: 48142 | G25: =IF(SUM(B25:F25)=0,"",SUM(B25:F25)) -> 52476
B26: June | D26: 8461 | E26: 4303 | F26: 42072 | G26: =IF(SUM(B26:F26)=0,"",SUM(B26:F26)) -> 54836
B27: July | D27: 8958 | E27: 7260 | F27: 49192 | G27: =IF(SUM(B27:F27)=0,"",SUM(B27:F27)) -> 65410
B28: August | D28: 6961 | E28: 3180 | F28: 46296 | G28: =IF(SUM(B28:F28)=0,"",SUM(B28:F28)) -> 56437
B29: September | D29: 5265 | E29: 5740 | F29: 44168 | G29: =IF(SUM(B29:F29)=0,"",SUM(B29:F29)) -> 55173
B30: October | D30: 8428 | E30: 4334 | F30: 52382 | G30: =IF(SUM(B30:F30)=0,"",SUM(B30:F30)) -> 65144
B31: November | D31: 7813 | E31: 4836 | F31: 59640 | G31: =IF(SUM(B31:F31)=0,"",SUM(B31:F31)) -> 72289
B32: December | D32: 4969 | E32: 3349 | F32: 43565 | G32: =IF(SUM(B32:F32)=0,"",SUM(B32:F32)) -> 51883
A33: 2025 | B33: January | D33: 5309 | E33: 3152 | F33: 46301 | G33: =IF(SUM(B33:F33)=0,"",SUM(B33:F33)) -> 54762
B34: February | D34: 4185 | E34: 6181 | F34: 54617 | G34: =IF(SUM(B34:F34)=0,"",SUM(B34:F34)) -> 64983
B35: March | D35: 8024 | E35: 7842 | F35: 51486 | G35: =IF(SUM(B35:F35)=0,"",SUM(B35:F35)) -> 67352
B36: April | D36: 5951 | E36: 7541 | F36: 61605 | G36: =IF(SUM(B36:F36)=0,"",SUM(B36:F36)) -> 75097
B37: May | D37: 8324 | E37: 5347 | F37: 66954 | G37: =IF(SUM(B37:F37)=0,"",SUM(B37:F37)) -> 80625
B38: June | D38: 5068 | E38: 4561 | F38: 61381 | G38: =IF(SUM(B38:F38)=0,"",SUM(B38:F38)) -> 71010
B39: July | D39: 5549 | E39: 4682 | F39: 49528 | G39: =IF(SUM(B39:F39)=0,"",SUM(B39:F39)) -> 59759
B40: August | D40: 9047 | E40: 4482 | F40: 45517 | G40: =IF(SUM(B40:F40)=0,"",SUM(B40:F40)) -> 59046
B41: September | D41: 11037 | E41: 8356 | F41: 53366 | G41: =IF(SUM(B41:F41)=0,"",SUM(B41:F41)) -> 72759
B42: October | D42: 6030 | E42: 7517 | F42: 56357 | G42: =IF(SUM(B42:F42)=0,"",SUM(B42:F42)) -> 69904
B43: November | D43: 13380 | E43: 2890 | F43: 52067 | G43: =IF(SUM(B43:F43)=0,"",SUM(B43:F43)) -> 68337
...

Sheet Table 8
A1: Table 8
A2: Dwelling Starts - Seasonally Adjusted at Annual Rates1
A5: Period | D5: St. John's | E5: Halifax | F5: Moncton | G5: Saint John | H5: Fredericton
A6: 2024 2 | D6: 871 | E6: 5081 | F6: 2997 | G6: 767 | H6: 749
A7: 2025 2 | D7: 1037 | E7: 7000 | F7: 2800 | G7: 666 | H7: 1427
A8: 2024 | B8: January | D8: 1072 | E8: 4279 | F8: 1385 | G8: 1334 | H8: 343
B9: February | D9: 519 | E9: 10979 | F9: 2270 | G9: 1695 | H9: 320
B10: March | D10: 147 | E10: 6179 | F10: 430 | G10: 224 | H10: 325
B11: April | D11: 668 | E11: 5954 | F11: 2133 | G11: 206 | H11: 375
B12: May | D12: 585 | E12: 6411 | F12: 4626 | G12: 556 | H12: 1091
B13: June | D13: 1027 | E13: 9055 | F13: 2572 | G13: 1105 | H13: 795
B14: July | D14: 778 | E14: 3707 | F14: 2356 | G14: 593 | H14: 446
B15: August | D15: 1102 | E15: 2452 | F15: 5113 | G15: 492 | H15: 1892
B16: September | D16: 915 | E16: 2618 | F16: 5249 | G16: 1126 | H16: 653
B17: October | D17: 1192 | E17: 2061 | F17: 3229 | G17: 259 | H17: 815
B18: November | D18: 1365 | E18: 3640 | F18: 3034 | G18: 883 | H18: 1621
B19: December | D19: 829 | E19: 3796 | F19: 3512 | G19: 738 | H19: 313
A20: 2025 | B20: January | D20: 825 | E20: 6392 | F20: 476 | G20: 545 | H20: 347
B21: February | D21: 852 | E21: 5674 | F21: 3432 | G21: 178 | H21: 344
B22: March | D22: 782 | E22: 5171 | F22: 2183 | G22: 362 | H22: 1532
B23: April | D23: 1355 | E23: 11011 | F23: 1740 | G23: 189 | H23: 216
B24: May | D24: 1009 | E24: 6643 | F24: 3434 | G24: 806 | H24: 1526
B25: June | D25: 976 | E25: 5536 | F25: 3733 | G25: 673 | H25: 2327
B26: July | D26: 1169 | E26: 14105 | F26: 4231 | G26: 768 | H26: 2934
B27: August | D27: 880 | E27: 5406 | F27: 4294 | G27: 429 | H27: 848
B28: September | D28: 1177 | E28: 4333 | F28: 1716 | G28: 1151 | H28: 698
B29: October | D29: 975 | E29: 6733 | F29: 1333 | G29: 458 | H29: 2381
B30: November | D30: 1558 | E30: 4783 | F30: 5362 | G30: 1582 | H30: 3150
B31: December | D31: 937 | E31: 8405 | F31: 1764 | G31: 848 | H31: 563
A32: 2026 | B32: January | D32: 1012 | E32: 3504 | F32: 2335 | G32: 463 | H32: 1361
B33: February | D33: 842 | E33: 5137 | F33: 1462 | G33: 282 | H33: 212
B34: March
B35: April
B36: May
B37: June
B38: July
B39: August
B40: September
B41: October
B42: November
...

Sheet Table 9
A1: Table 9
A2: Dwelling Starts - Seasonally Adjusted at Annual Rates1
A5: Period | D5: Québec | E5: Sherbrooke | F5: Trois-Rivières | G5: Montréal | H5: Gatineau | I5: Saguenay | J5: Drummondville
A6: 2024 2 | D6: 6905 | E6: 1932 | F6: 1684 | G6: 17570 | H6: 3655 | I6: 908 | J6: 1060
A7: 2025 2 | D7: 8583 | E7: 1813 | F7: 1428 | G7: 27777 | H7: 2120 | I7: 797 | J7: 1389
A8: 2024 | B8: January | D8: 6964 | E8: 1082 | F8: 1202 | G8: 14975 | H8: 2514 | I8: 557 | J8: 182
B9: February | D9: 3943 | E9: 550 | F9: 1754 | G9: 10438 | H9: 1876 | I9: 485 | J9: 633
B10: March | D10: 6633 | E10: 1904 | F10: 485 | G10: 9994 | H10: 2082 | I10: 687 | J10: 558
B11: April | D11: 8177 | E11: 977 | F11: 392 | G11: 13763 | H11: 790 | I11: 109 | J11: 657
B12: May | D12: 7581 | E12: 1440 | F12: 1773 | G12: 28275 | H12: 9858 | I12: 348 | J12: 847
B13: June | D13: 9852 | E13: 2572 | F13: 1052 | G13: 34944 | H13: 1718 | I13: 447 | J13: 1134
B14: July | D14: 7443 | E14: 776 | F14: 704 | G14: 8815 | H14: 3773 | I14: 450 | J14: 2650
B15: August | D15: 5111 | E15: 1460 | F15: 1762 | G15: 15656 | H15: 1378 | I15: 398 | J15: 1300
B16: September | D16: 7127 | E16: 3246 | F16: 7928 | G16: 13051 | H16: 4453 | I16: 788 | J16: 1000
B17: October | D17: 5031 | E17: 4282 | F17: 451 | G17: 16428 | H17: 8443 | I17: 3638 | J17: 1111
B18: November | D18: 12734 | E18: 3182 | F18: 985 | G18: 31302 | H18: 4165 | I18: 1151 | J18: 1818
B19: December | D19: 2016 | E19: 1710 | F19: 1719 | G19: 13353 | H19: 2821 | I19: 1848 | J19: 829
A20: 2025 | B20: January | D20: 6616 | E20: 794 | F20: 643 | G20: 31117 | H20: 4106 | I20: 737 | J20: 452
B21: February | D21: 6547 | E21: 1093 | F21: 473 | G21: 11094 | H21: 1423 | I21: 915 | J21: 1022
B22: March | D22: 5203 | E22: 1444 | F22: 1425 | G22: 23633 | H22: 1491 | I22: 586 | J22: 1643
B23: April | D23: 8090 | E23: 2306 | F23: 978 | G23: 22884 | H23: 1883 | I23: 413 | J23: 940
B24: May | D24: 24353 | E24: 887 | F24: 3886 | G24: 31620 | H24: 5037 | I24: 841 | J24: 1197
B25: June | D25: 6993 | E25: 3338 | F25: 1226 | G25: 32021 | H25: 1870 | I25: 295 | J25: 2009
B26: July | D26: 8267 | E26: 812 | F26: 755 | G26: 28216 | H26: 3304 | I26: 806 | J26: 1235
B27: August | D27: 4923 | E27: 624 | F27: 1567 | G27: 20376 | H27: 1726 | I27: 450 | J27: 1075
B28: September | D28: 8417 | E28: 2849 | F28: 1288 | G28: 30951 | H28: 681 | I28: 922 | J28: 1724
B29: October | D29: 12511 | E29: 1575 | F29: 2708 | G29: 33614 | H29: 1304 | I29: 746 | J29: 1157
B30: November | D30: 8999 | E30: 3478 | F30: 1391 | G30: 39026 | H30: 1273 | I30: 946 | J30: 2416
B31: December | D31: 1923 | E31: 2570 | F31: 793 | G31: 29089 | H31: 1421 | I31: 1888 | J31: 1816
A32: 2026 | B32: January | D32: 3735 | E32: 727 | F32: 723 | G32: 17579 | H32: 2201 | I32: 1013 | J32: 920
B33: February | D33: 8868 | E33: 2691 | F33: 242 | G33: 12998 | H33: 2855 | I33: 496 | J33: 652
B34: March
B35: April
B36: May
B37: June
B38: July
B39: August
B40: September
B41: October
B42: November
...

Sheet Table 10
A1: Table 10
A2: Dwelling Starts - Seasonally Adjusted at Annual Rates1
A5: Period | D5: Ottawa | E5: Kingston | F5: Belleville - Quinte West | G5: Peterborough | H5: Oshawa | I5: Toronto
A6: 2024 2 | D6: 7894 | E6: 1015 | F6: 387 | G6: 313 | H6: 1591 | I6: 37718
A7: 2025 2 | D7: 10864 | E7: 1094 | F7: 636 | G7: 100 | H7: 1014 | I7: 26087
A8: 2024 | B8: January | D8: 3370 | E8: 385 | F8: 205 | G8: 131 | H8: 4311 | I8: 49112
B9: February | D9: 5511 | E9: 485 | F9: 1169 | G9: 117 | H9: 1178 | I9: 57342
B10: March | D10: 6822 | E10: 251 | F10: 448 | G10: 174 | H10: 1290 | I10: 42221
B11: April | D11: 4723 | E11: 384 | F11: 294 | G11: 277 | H11: 1499 | I11: 37316
B12: May | D12: 8361 | E12: 382 | F12: 206 | G12: 131 | H12: 1875 | I12: 54390
B13: June | D13: 6225 | E13: 334 | F13: 256 | G13: 837 | H13: 2890 | I13: 34424
B14: July | D14: 10957 | E14: 264 | F14: 253 | G14: 107 | H14: 788 | I14: 65143
B15: August | D15: 7240 | E15: 1285 | F15: 362 | G15: 723 | H15: 3268 | I15: 24783
B16: September | D16: 17859 | E16: 320 | F16: 556 | G16: 267 | H16: 492 | I16: 19753
B17: October | D17: 7243 | E17: 2223 | F17: 314 | G17: 272 | H17: 553 | I17: 28821
B18: November | D18: 9007 | E18: 261 | F18: 470 | G18: 730 | H18: 612 | I18: 26310
B19: December | D19: 7295 | E19: 5705 | F19: 311 | G19: 53 | H19: 446 | I19: 12078
A20: 2025 | B20: January | D20: 6512 | E20: 2152 | F20: 181 | G20: 155 | H20: 213 | I20: 29231
B21: February | D21: 12671 | E21: 413 | F21: 2174 | G21: 350 | H21: 305 | I21: 18872
B22: March | D22: 7774 | E22: 245 | F22: 178 | G22: 50 | H22: 846 | I22: 14843
B23: April | D23: 17142 | E23: 617 | F23: 160 | G23: 14 | H23: 819 | I23: 28134
B24: May | D24: 7398 | E24: 241 | F24: 99 | G24: 69 | H24: 956 | I24: 42880
B25: June | D25: 12218 | E25: 6178 | F25: 435 | G25: 79 | H25: 735 | I25: 20716
B26: July | D26: 13945 | E26: 385 | F26: 1246 | G26: 276 | H26: 1163 | I26: 20074
B27: August | D27: 4283 | E27: 246 | F27: 165 | G27: 83 | H27: 2797 | I27: 25236
B28: September | D28: 5572 | E28: 52 | F28: 1083 | G28: 117 | H28: 1054 | I28: 43354
B29: October | D29: 8524 | E29: 1105 | F29: 603 | G29: 78 | H29: 753 | I29: 16607
B30: November | D30: 11341 | E30: 644 | F30: 362 | G30: 60 | H30: 1315 | I30: 23603
B31: December | D31: 22709 | E31: 1010 | F31: 972 | G31: 86 | H31: 1064 | I31: 29736
A32: 2026 | B32: January | D32: 6753 | E32: 552 | F32: 175 | G32: 57 | H32: 1242 | I32: 28382
B33: February | D33: 14612 | E33: 167 | F33: 19 | G33: 101 | H33: 1251 | I33: 13738
B34: March
B35: April
B36: May
B37: June
B38: July
B39: August
B40: September
B41: October
B42: November
...

Sheet Table 11
A1: Table 11
A2: Dwelling Starts - Seasonally Adjusted at Annual Rates1
A4: Period | D4: Hamilton | E4: St Catharines-Niagara | F4: Kitchener-Cambridge-Waterloo | G4: Brantford | H4: Guelph
A5: Period
A6: 2024 2 | D6: 2627 | E6: 1743 | F6: 3411 | G6: 359 | H6: 452
A7: 2025 2 | D7: 3146 | E7: 2514 | F7: 4306 | G7: 1650 | H7: 321
A8: 2024 | B8: January | D8: 3255 | E8: 1383 | F8: 2331 | G8: 328 | H8: 54
B9: February | D9: 2566 | E9: 2050 | F9: 2066 | G9: 415 | H9: 1223
B10: March | D10: 714 | E10: 1602 | F10: 1461 | G10: 178 | H10: 128
B11: April | D11: 723 | E11: 1735 | F11: 6159 | G11: 176 | H11: 425
B12: May | D12: 5423 | E12: 3142 | F12: 802 | G12: 72 | H12: 91
B13: June | D13: 262 | E13: 885 | F13: 6871 | G13: 60 | H13: 414
B14: July | D14: 3784 | E14: 1644 | F14: 2847 | G14: 310 | H14: 1359
B15: August | D15: 1424 | E15: 2334 | F15: 3955 | G15: 263 | H15: 340
B16: September | D16: 5397 | E16: 743 | F16: 1764 | G16: 783 | H16: 614
B17: October | D17: 1476 | E17: 1130 | F17: 3714 | G17: 726 | H17: 109
B18: November | D18: 651 | E18: 3552 | F18: 942 | G18: 883 | H18: 445
B19: December | D19: 5819 | E19: 667 | F19: 7962 | G19: 133 | H19: 217
A20: 2025 | B20: January | D20: 438 | E20: 1442 | F20: 2554 | G20: 3186 | H20: 54
B21: February | D21: 5176 | E21: 2533 | F21: 3549 | G21: 234 | H21: 43
B22: March | D22: 412 | E22: 1238 | F22: 4333 | G22: 1181 | H22: 46
B23: April | D23: 2526 | E23: 966 | F23: 3108 | G23: 3590 | H23: 126
